<?xml version="1.0" ?>
<!-- Generated using onshape-to-robot -->
<!-- Onshape https://cad.onshape.com/documents/a9a7e86a17f28ee4ee62053e/w/e5c2325ac4afc9cec5a29721/e/8ca5f896267b7130065f5bbb -->
<mujoco model="humanoid_mockup_v0.1">
  <compiler angle="radian" meshdir="assets" autolimits="true"/>
  <default>
    <default class="humanoid_mockup_v0.1">
      <joint frictionloss="0.1" armature="0.005"/>
      <position kp="50" dampratio="1"/>
      <default class="visual">
        <geom type="mesh" contype="0" conaffinity="0" group="2"/>
      </default>
      <default class="collision">
        <geom group="3"/>
      </default>
    </default>
  </default>
  <!-- Additional steadywin_GIM6010-8.xml -->
  <default>
    <default class="steadywin_GIM6010_8">
      <!-- need to be identified -->
      <geom contype="0" conaffinity="0"/>
      <joint damping="0.1" frictionloss="0.05" armature="0.002"/>
      <position kp="20.0" kv="0.0" forcerange="-5.0 5.0"/>
    </default>
  </default>
  <!-- Additional sensors.xml -->
  <sensor>
    <gyro site="imu" name="gyro"/>
    <velocimeter site="imu" name="local_linvel"/>
    <accelerometer site="imu" name="accelerometer"/>
    <framezaxis objtype="site" objname="imu" name="upvector"/>
    <framexaxis objtype="site" objname="imu" name="forwardvector"/>
    <framelinvel objtype="site" objname="imu" name="global_linvel"/>
    <frameangvel objtype="site" objname="imu" name="global_angvel"/>
    <framepos objtype="site" objname="imu" name="position"/>
    <framequat objtype="site" objname="imu" name="orientation"/>
    <framelinvel objtype="site" objname="right_foot" name="right_foot_global_linvel"/>
    <framelinvel objtype="site" objname="left_foot" name="left_foot_global_linvel"/>
    <framexaxis objtype="site" objname="left_foot" name="left_foot_upvector"/>
    <framexaxis objtype="site" objname="right_foot" name="right_foot_upvector"/>
    <framepos objtype="site" objname="left_foot" name="left_foot_pos"/>
    <framepos objtype="site" objname="right_foot" name="right_foot_pos"/>
  </sensor>
  <worldbody>
    <!-- Link trunk_2 -->
    <body name="trunk_2" pos="0 0 0.55" quat="1 0 0 0" childclass="humanoid_mockup_v0.1">
      <freejoint name="trunk_2_freejoint"/>
      <inertial pos="0.187302 -0.0485955 0.0364186" mass="5.776" fullinertia="0.0497042 0.0436902 0.0147819 -1.15556e-33 2.40494e-18 -4.33681e-19"/>
      <!-- Part gim6010_8 -->
      <geom type="mesh" class="visual" pos="0.187302 -0.0185955 -0.0752399" quat="0.707107 -0.707107 0 0" mesh="gim6010_8" material="gim6010_8_material"/>
      <!-- Part trunk_2 -->
      <geom type="mesh" class="visual" pos="0.187302 -0.0485955 -0.0752399" quat="1 0 0 0" mesh="trunk" material="trunk_material"/>
      <!-- Part gim6010_8_2 -->
      <geom type="mesh" class="visual" pos="0.187302 -0.118596 -0.0752399" quat="0.707107 -0.707107 0 0" mesh="gim6010_8" material="gim6010_8_material"/>
      <!-- Frame trunk -->
      <site group="3" name="trunk" pos="0.187302 -0.0485955 0.0247601" quat="1 0 0 0"/>
      <!-- Frame imu -->
      <site group="3" name="imu" pos="0.187302 -0.0485955 0.17476" quat="1 0 0 0"/>
      <!-- Link left_hip_pitch_to_roll -->
      <body name="left_hip_pitch_to_roll" pos="0.187302 0.0214045 -0.0752399" quat="0.707107 -0.707107 0 0">
        <!-- Joint from trunk_2 to left_hip_pitch_to_roll -->
        <joint axis="0 0 1" name="left_hip_pitch" type="hinge" class="steadywin_GIM6010_8"/>
        <inertial pos="-0.00539992 -2.00931e-10 0.046622" mass="0.517883" fullinertia="0.000465444 0.000403205 0.000324921 -3.16452e-12 1.58161e-06 1.79213e-12"/>
        <!-- Part left_hip_pitch_to_roll -->
        <geom type="mesh" class="visual" pos="0 0 -0.07" quat="0.707107 0.707107 -0 -0" mesh="left_hip_pitch_to_roll" material="left_hip_pitch_to_roll_material"/>
        <!-- Part gim6010_8_3 -->
        <geom type="mesh" class="visual" pos="0.02 0 0.05" quat="0.5 0.5 -0.5 -0.5" mesh="gim6010_8" material="gim6010_8_material"/>
        <!-- Link left_hip_roll_to_yaw -->
        <body name="left_hip_roll_to_yaw" pos="0.02 0 0.05" quat="0 -0.707107 0 -0.707107">
          <!-- Joint from left_hip_pitch_to_roll to left_hip_roll_to_yaw -->
          <joint axis="0 0 1" name="left_hip_roll" type="hinge" class="steadywin_GIM6010_8"/>
          <inertial pos="2.00931e-10 -0.0558222 -0.0146001" mass="0.517883" fullinertia="0.000696527 0.000428388 0.0006553 -7.24941e-12 -3.16452e-12 -0.000148243"/>
          <!-- Part left_hip_roll_to_yaw -->
          <geom type="mesh" class="visual" pos="-0.12 0 -0.02" quat="0.5 -0.5 -0.5 -0.5" mesh="left_hip_roll_to_yaw" material="left_hip_roll_to_yaw_material"/>
          <!-- Part gim6010_8_4 -->
          <geom type="mesh" class="visual" pos="2.77556e-17 -0.09 -0.02" quat="0.5 -0.5 -0.5 -0.5" mesh="gim6010_8" material="gim6010_8_material"/>
          <!-- Link left_hip_yaw_to_knee -->
          <body name="left_hip_yaw_to_knee" pos="2.77556e-17 -0.09 -0.02" quat="0.5 0.5 -0.5 0.5">
            <!-- Joint from left_hip_roll_to_yaw to left_hip_yaw_to_knee -->
            <joint axis="0 0 1" name="left_hip_yaw" type="hinge" class="steadywin_GIM6010_8"/>
            <inertial pos="6.01852e-10 -0.00240575 0.0825501" mass="0.688" fullinertia="0.00139735 0.00147146 0.000460223 1.06662e-11 -1.67017e-11 4.0779e-05"/>
            <!-- Part left_hip_yaw_to_knee -->
            <geom type="mesh" class="visual" pos="0 0.12 -0.09" quat="0 1 0 0" mesh="left_hip_yaw_to_knee" material="left_hip_yaw_to_knee_material"/>
            <!-- Part gim6010_8_5 -->
            <geom type="mesh" class="visual" pos="0 0.02 0.11" quat="0.707107 0.707107 -0 -0" mesh="gim6010_8" material="gim6010_8_material"/>
            <!-- Link left_knee_to_ankle_pitch -->
            <body name="left_knee_to_ankle_pitch" pos="0 0.02 0.11" quat="0.707107 -0.707107 0 0">
              <!-- Joint from left_hip_yaw_to_knee to left_knee_to_ankle_pitch -->
              <joint axis="0 0 1" name="left_knee" type="hinge" class="steadywin_GIM6010_8"/>
              <inertial pos="-4.82013e-08 -0.149239 -0.0200003" mass="0.788" fullinertia="0.00357604 0.000553221 0.00362879 1.87021e-09 2.32028e-09 -0.000244816"/>
              <!-- Part left_knee_to_ankle_pitch -->
              <geom type="mesh" class="visual" pos="0 0.2 0.1" quat="0.707107 -0.707107 0 0" mesh="left_knee_to_ankle_pitch" material="left_knee_to_ankle_pitch_material"/>
              <!-- Part gim6010_8_6 -->
              <geom type="mesh" class="visual" pos="0 -0.2 -9.71445e-17" quat="0 1 0 0" mesh="gim6010_8" material="gim6010_8_material"/>
              <!-- Link left_foot_2 -->
              <body name="left_foot_2" pos="0 -0.2 -9.71445e-17" quat="1 0 2.22045e-16 0">
                <!-- Joint from left_knee_to_ankle_pitch to left_foot_2 -->
                <joint axis="0 0 1" name="left_ankle_pitch" type="hinge" class="steadywin_GIM6010_8"/>
                <inertial pos="0.0194455 -0.0403674 -0.00944551" mass="0.2" fullinertia="0.000264539 0.000619609 0.000659084 6.66303e-05 4.10475e-05 -6.66303e-05"/>
                <!-- Part left_foot_2 -->
                <geom type="mesh" class="visual" pos="0 0.4 0.1" quat="0.707107 -0.707107 0 0" mesh="left_foot" material="left_foot_material"/>
                <geom type="mesh" class="collision" pos="0 0.4 0.1" quat="0.707107 -0.707107 0 0" mesh="left_foot" material="left_foot_material" name="left_foot_contact"/>
                <!-- Frame left_foot -->
                <site group="3" name="left_foot" pos="0.03 -0.065 -0.02" quat="0.707107 -0.707107 0 0"/>
              </body>
            </body>
          </body>
        </body>
      </body>
      <!-- Link right_hip_pitch_to_roll -->
      <body name="right_hip_pitch_to_roll" pos="0.187302 -0.118596 -0.0752399" quat="0.707107 -0.707107 0 0">
        <!-- Joint from trunk_2 to right_hip_pitch_to_roll -->
        <joint axis="0 0 1" name="right_hip_pitch" type="hinge" class="steadywin_GIM6010_8"/>
        <inertial pos="-0.00539992 2.00931e-10 -0.046622" mass="0.517883" fullinertia="0.000465444 0.000403205 0.000324921 3.16452e-12 -1.58161e-06 1.79213e-12"/>
        <!-- Part gim6010_8_7 -->
        <geom type="mesh" class="visual" pos="-0.02 0 -0.05" quat="0.707107 0 0.707107 0" mesh="gim6010_8" material="gim6010_8_material"/>
        <!-- Part right_hip_pitch_to_roll -->
        <geom type="mesh" class="visual" pos="0 0 0.07" quat="0.707107 0.707107 -0 -0" mesh="right_hip_pitch_to_roll" material="right_hip_pitch_to_roll_material"/>
        <!-- Link right_hip_roll_to_yaw -->
        <body name="right_hip_roll_to_yaw" pos="0.02 0 -0.05" quat="0.707107 -0 -0.707107 -0">
          <!-- Joint from right_hip_pitch_to_roll to right_hip_roll_to_yaw -->
          <joint axis="0 0 1" name="right_hip_roll" type="hinge" class="steadywin_GIM6010_8"/>
          <inertial pos="2.00931e-10 0.0558222 0.0146001" mass="0.517883" fullinertia="0.000696527 0.000428388 0.0006553 7.24941e-12 3.16452e-12 -0.000148243"/>
          <!-- Part right_hip_roll_to_yaw -->
          <geom type="mesh" class="visual" pos="0.12 0 0.02" quat="0.5 0.5 0.5 -0.5" mesh="right_hip_roll_to_yaw" material="right_hip_roll_to_yaw_material"/>
          <!-- Part gim6010_8_8 -->
          <geom type="mesh" class="visual" pos="-2.77556e-17 0.05 0.02" quat="0.5 -0.5 0.5 0.5" mesh="gim6010_8" material="gim6010_8_material"/>
          <!-- Link right_hip_yaw_to_knee -->
          <body name="right_hip_yaw_to_knee" pos="-2.77556e-17 0.09 0.02" quat="0.5 0.5 0.5 -0.5">
            <!-- Joint from right_hip_roll_to_yaw to right_hip_yaw_to_knee -->
            <joint axis="0 0 1" name="right_hip_yaw" type="hinge" class="steadywin_GIM6010_8"/>
            <inertial pos="-6.01852e-10 -0.00240575 -0.0825501" mass="0.688" fullinertia="0.00139735 0.00147146 0.000460223 -1.06662e-11 -1.67017e-11 -4.0779e-05"/>
            <!-- Part right_hip_yaw_to_knee -->
            <geom type="mesh" class="visual" pos="0 0.12 0.09" quat="1 0 1.218e-27 -1.89327e-29" mesh="right_hip_yaw_to_knee" material="right_hip_yaw_to_knee_material"/>
            <!-- Part gim6010_8_9 -->
            <geom type="mesh" class="visual" pos="0 -0.02 -0.11" quat="0.707107 -0.707107 -0 -1.45147e-48" mesh="gim6010_8" material="gim6010_8_material"/>
            <!-- Link right_knee_to_ankle_pitch -->
            <body name="right_knee_to_ankle_pitch" pos="0 0.02 -0.11" quat="0.707107 0.707107 -0 1.45147e-48">
              <!-- Joint from right_hip_yaw_to_knee to right_knee_to_ankle_pitch -->
              <joint axis="0 0 1" name="right_knee" type="hinge" class="steadywin_GIM6010_8"/>
              <inertial pos="4.82013e-08 -0.149239 0.0200003" mass="0.788" fullinertia="0.00357604 0.000553221 0.00362879 -1.87021e-09 2.32028e-09 0.000244816"/>
              <!-- Part right_knee_to_ankle_pitch -->
              <geom type="mesh" class="visual" pos="0 0.2 -0.1" quat="0.707107 -0.707107 0 -1.93529e-48" mesh="right_knee_to_ankle_pitch" material="right_knee_to_ankle_pitch_material"/>
              <!-- Part gim6010_8_10 -->
              <geom type="mesh" class="visual" pos="0 -0.2 0.04" quat="0 1 0 0" mesh="gim6010_8" material="gim6010_8_material"/>
              <!-- Link right_foot_2 -->
              <body name="right_foot_2" pos="0 -0.2 1.11022e-16" quat="1 -0 -0 4.37906e-46">
                <!-- Joint from right_knee_to_ankle_pitch to right_foot_2 -->
                <joint axis="0 0 1" name="right_ankle_pitch" type="hinge" class="steadywin_GIM6010_8"/>
                <inertial pos="0.0194455 -0.0403674 0.00944551" mass="0.2" fullinertia="0.000264539 0.000619609 0.000659084 6.66303e-05 -4.10475e-05 6.66303e-05"/>
                <!-- Part right_foot_2 -->
                <geom type="mesh" class="visual" pos="0 0.4 -0.1" quat="0.707107 -0.707107 -0 1.45147e-48" mesh="right_foot" material="right_foot_material"/>
                <geom type="mesh" class="collision" pos="0 0.4 -0.1" quat="0.707107 -0.707107 -0 1.45147e-48" mesh="right_foot" material="right_foot_material" name="right_foot_contact"/>
                <!-- Frame right_foot -->
                <site group="3" name="right_foot" pos="0.03 -0.065 0.02" quat="0.707107 -0.707107 -0 1.45147e-48"/>
              </body>
            </body>
          </body>
        </body>
      </body>
    </body>
  </worldbody>
  <asset>
    <mesh file="right_knee_to_ankle_pitch.stl"/>
    <mesh file="right_foot.stl"/>
    <mesh file="left_hip_roll_to_yaw.stl"/>
    <mesh file="left_hip_pitch_to_roll.stl"/>
    <mesh file="right_hip_roll_to_yaw.stl"/>
    <mesh file="trunk.stl"/>
    <mesh file="left_knee_to_ankle_pitch.stl"/>
    <mesh file="left_foot.stl"/>
    <mesh file="right_hip_yaw_to_knee.stl"/>
    <mesh file="right_hip_pitch_to_roll.stl"/>
    <mesh file="gim6010_8.stl"/>
    <mesh file="left_hip_yaw_to_knee.stl"/>
    <material name="gim6010_8_material" rgba="0.301961 0.301961 0.301961 1"/>
    <material name="trunk_material" rgba="0.615686 0.811765 0.929412 1"/>
    <material name="left_hip_pitch_to_roll_material" rgba="0.647059 0.647059 0.647059 1"/>
    <material name="left_hip_roll_to_yaw_material" rgba="0.231373 0.380392 0.705882 1"/>
    <material name="left_hip_yaw_to_knee_material" rgba="0.917647 0.917647 0.917647 1"/>
    <material name="left_knee_to_ankle_pitch_material" rgba="0.768627 0.886275 0.952941 1"/>
    <material name="left_foot_material" rgba="0.972549 0.529412 0.00392157 1"/>
    <material name="right_hip_pitch_to_roll_material" rgba="0.647059 0.647059 0.647059 1"/>
    <material name="right_hip_roll_to_yaw_material" rgba="0.231373 0.380392 0.705882 1"/>
    <material name="right_hip_yaw_to_knee_material" rgba="0.917647 0.917647 0.917647 1"/>
    <material name="right_knee_to_ankle_pitch_material" rgba="0.768627 0.886275 0.952941 1"/>
    <material name="right_foot_material" rgba="0.972549 0.529412 0.00392157 1"/>
  </asset>
  <actuator>
    <position class="steadywin_GIM6010_8" name="left_hip_pitch" joint="left_hip_pitch"/>
    <position class="steadywin_GIM6010_8" name="left_hip_roll" joint="left_hip_roll"/>
    <position class="steadywin_GIM6010_8" name="left_hip_yaw" joint="left_hip_yaw"/>
    <position class="steadywin_GIM6010_8" name="left_knee" joint="left_knee"/>
    <position class="steadywin_GIM6010_8" name="left_ankle_pitch" joint="left_ankle_pitch"/>
    <position class="steadywin_GIM6010_8" name="right_hip_pitch" joint="right_hip_pitch"/>
    <position class="steadywin_GIM6010_8" name="right_hip_roll" joint="right_hip_roll"/>
    <position class="steadywin_GIM6010_8" name="right_hip_yaw" joint="right_hip_yaw"/>
    <position class="steadywin_GIM6010_8" name="right_knee" joint="right_knee"/>
    <position class="steadywin_GIM6010_8" name="right_ankle_pitch" joint="right_ankle_pitch"/>
  </actuator>
  <equality/>
</mujoco>
