<?xml version="1.0" ?>
<!-- Generated using onshape-to-robot -->
<!-- Onshape https://cad.onshape.com/documents/a9a7e86a17f28ee4ee62053e/w/e5c2325ac4afc9cec5a29721/e/8ca5f896267b7130065f5bbb -->
<mujoco model="humanoid_mockup_v0.1">
  <!-- <compiler angle="radian" meshdir="assets" autolimits="true"/> -->
  <option iterations="1" ls_iterations="5">
    <flag eulerdamp="disable"/>
  </option>
  <compiler angle="radian" meshdir="assets"/>
  <default>
    <default class="humanoid_mockup_v0.1">
      <joint frictionloss="0.1" armature="0.005"/>
      <position kp="50" dampratio="1"/>
      <default class="visual">
        <geom type="mesh" contype="0" conaffinity="0" group="2"/>
      </default>
      <default class="collision">
        <geom group="3"/>
      </default>
    </default>
  </default>
  <!-- Additional steadywin_GIM6010-8.xml -->
  <default>
    <default class="steadywin_GIM6010_8">
      <!-- need to be identified -->
      <geom contype="0" conaffinity="0"/>
      <joint damping="0.8" frictionloss="0.2" armature="0.01"/>
      <position kp="40.0" kv="0.0" forcerange="-11.0 11.0"/>
    </default>
  </default>
  <!-- Additional sensors.xml -->
  <sensor>
    <gyro site="imu" name="gyro"/>
    <velocimeter site="imu" name="local_linvel"/>
    <accelerometer site="imu" name="accelerometer"/>
    <framezaxis objtype="site" objname="imu" name="upvector"/>
    <framexaxis objtype="site" objname="imu" name="forwardvector"/>
    <framelinvel objtype="site" objname="imu" name="global_linvel"/>
    <frameangvel objtype="site" objname="imu" name="global_angvel"/>
    <framepos objtype="site" objname="imu" name="position"/>
    <framequat objtype="site" objname="imu" name="orientation"/>
    <framelinvel objtype="site" objname="right_foot" name="right_foot_global_linvel"/>
    <framelinvel objtype="site" objname="left_foot" name="left_foot_global_linvel"/>
    <framexaxis objtype="site" objname="left_foot" name="left_foot_upvector"/>
    <framexaxis objtype="site" objname="right_foot" name="right_foot_upvector"/>
    <framepos objtype="site" objname="left_foot" name="left_foot_pos"/>
    <framepos objtype="site" objname="right_foot" name="right_foot_pos"/>
  </sensor>
  <worldbody>
    <!-- Link trunk_2 -->
    <body name="trunk_2" pos="0 0 0.55" quat="1 0 0 0" childclass="humanoid_mockup_v0.1">
      <freejoint name="trunk_2_freejoint"/>
      <inertial pos="0.120022 0.0611056 0.0576308" mass="5.776" fullinertia="0.0497042 0.0436902 0.0147819 5.50334e-11 -1.13903e-18 -4.30554e-10"/>
      <!-- Part gim6010_8 -->
      <geom type="mesh" class="visual" pos="0.120022 0.0911056 -0.0540277" quat="0.707107 -0.707107 -3.23536e-09 3.23536e-09" mesh="gim6010_8" material="gim6010_8_material"/>
      <!-- Part trunk_2 -->
      <geom type="mesh" class="visual" pos="0.120022 0.0611056 -0.0540277" quat="1 -7.44689e-09 -0 4.57549e-09" mesh="trunk" material="trunk_material"/>
      <!-- Part gim6010_8_2 -->
      <geom type="mesh" class="visual" pos="0.120022 -0.00889443 -0.0540277" quat="0.707107 -0.707107 -3.23536e-09 3.23536e-09" mesh="gim6010_8" material="gim6010_8_material"/>
      <!-- Frame trunk -->
      <site group="3" name="trunk" pos="0.120022 0.0611056 0.0459723" quat="1 -7.44689e-09 -0 4.57549e-09"/>
      <!-- Frame imu -->
      <site group="3" name="imu" pos="0.120022 0.0611056 0.195972" quat="1 -7.44689e-09 -0 4.57549e-09"/>
      <!-- Link left_hip_pitch_to_roll -->
      <body name="left_hip_pitch_to_roll" pos="0.120022 0.131106 -0.0540277" quat="0.707107 -0.707107 5.37049e-09 1.18412e-08">
        <!-- Joint from trunk_2 to left_hip_pitch_to_roll -->
        <joint axis="0 0 1" name="left_hip_pitch" type="hinge" range="-1.5707963511359102 1.570796302453883" class="steadywin_GIM6010_8"/>
        <inertial pos="-0.00539992 -2.00931e-10 0.046622" mass="0.517883" fullinertia="0.000465444 0.000403205 0.000324921 -3.16452e-12 1.58161e-06 1.79213e-12"/>
        <!-- Part left_hip_pitch_to_roll -->
        <geom type="mesh" class="visual" pos="0 6.93889e-18 -0.07" quat="0.707107 0.707107 0 -3.63926e-25" mesh="left_hip_pitch_to_roll" material="left_hip_pitch_to_roll_material"/>
        <!-- Part gim6010_8_3 -->
        <geom type="mesh" class="visual" pos="0.02 0 0.05" quat="0.5 0.5 -0.5 -0.5" mesh="gim6010_8" material="gim6010_8_material"/>
        <!-- Link left_hip_roll_to_yaw -->
        <body name="left_hip_roll_to_yaw" pos="0.02 6.93889e-18 0.05" quat="1.44385e-16 -0.707107 1.11022e-16 -0.707107">
          <!-- Joint from left_hip_pitch_to_roll to left_hip_roll_to_yaw -->
          <joint axis="0 0 1" name="left_hip_roll" type="hinge" range="-0.3490658503988659 1.5707963267948966" class="steadywin_GIM6010_8"/>
          <inertial pos="2.00931e-10 -0.0558222 -0.0146001" mass="0.517883" fullinertia="0.000696527 0.000428388 0.0006553 -7.24941e-12 -3.16452e-12 -0.000148243"/>
          <!-- Part left_hip_roll_to_yaw -->
          <geom type="mesh" class="visual" pos="-0.12 0 -0.02" quat="0.5 -0.5 -0.5 -0.5" mesh="left_hip_roll_to_yaw" material="left_hip_roll_to_yaw_material"/>
          <!-- Part gim6010_8_4 -->
          <geom type="mesh" class="visual" pos="2.77556e-17 -0.09 -0.02" quat="0.5 -0.5 -0.5 -0.5" mesh="gim6010_8" material="gim6010_8_material"/>
          <!-- Link left_hip_yaw_to_knee -->
          <body name="left_hip_yaw_to_knee" pos="2.77556e-17 -0.09 -0.02" quat="0.5 0.5 -0.5 0.5">
            <!-- Joint from left_hip_roll_to_yaw to left_hip_yaw_to_knee -->
            <joint axis="0 0 1" name="left_hip_yaw" type="hinge" range="-1.570796331370385 1.5707963222194081" class="steadywin_GIM6010_8"/>
            <inertial pos="6.01852e-10 -0.00240575 0.0825501" mass="0.688" fullinertia="0.00139735 0.00147146 0.000460223 1.06662e-11 -1.67017e-11 4.0779e-05"/>
            <!-- Part left_hip_yaw_to_knee -->
            <geom type="mesh" class="visual" pos="1.38778e-17 0.12 -0.09" quat="0 1 0 0" mesh="left_hip_yaw_to_knee" material="left_hip_yaw_to_knee_material"/>
            <!-- Part gim6010_8_5 -->
            <geom type="mesh" class="visual" pos="1.38778e-17 0.02 0.11" quat="0.707107 0.707107 -0 -1.48992e-17" mesh="gim6010_8" material="gim6010_8_material"/>
            <!-- Link left_knee_to_ankle_pitch -->
            <body name="left_knee_to_ankle_pitch" pos="1.38778e-17 0.02 0.11" quat="0.707107 -0.707107 -1.92504e-10 -1.92504e-10">
              <!-- Joint from left_hip_yaw_to_knee to left_knee_to_ankle_pitch -->
              <joint axis="0 0 1" name="left_knee" type="hinge" range="-2.268928027048144 5.444842610619447e-10" class="steadywin_GIM6010_8"/>
              <inertial pos="-4.82013e-08 -0.149239 -0.0200003" mass="0.788" fullinertia="0.00357604 0.000553221 0.00362879 1.87021e-09 2.32028e-09 -0.000244816"/>
              <!-- Part left_knee_to_ankle_pitch -->
              <geom type="mesh" class="visual" pos="-1.38778e-17 0.2 0.1" quat="0.707107 -0.707107 -0 7.25026e-25" mesh="left_knee_to_ankle_pitch" material="left_knee_to_ankle_pitch_material"/>
              <!-- Part gim6010_8_6 -->
              <geom type="mesh" class="visual" pos="-2.77556e-17 -0.2 0" quat="0 1 0 0" mesh="gim6010_8" material="gim6010_8_material"/>
              <!-- Link left_foot_2 -->
              <body name="left_foot_2" pos="-2.77556e-17 -0.2 2.77556e-17" quat="1 0 -1.11022e-16 3.46945e-17">
                <!-- Joint from left_knee_to_ankle_pitch to left_foot_2 -->
                <joint axis="0 0 1" name="left_ankle_pitch" type="hinge" range="-1.5707963267948966 1.5707963267948966" class="steadywin_GIM6010_8"/>
                <inertial pos="0.0202559 -0.0527376 -0.0136201" mass="0.4" fullinertia="0.000426448 0.00107974 0.00139386 0.000143357 5.16919e-05 -0.000119141"/>
                <!-- Part left_foot_sole -->
                <geom type="mesh" class="visual" pos="0 0.4 0.1" quat="0.707107 -0.707107 -0 3.77957e-24" mesh="left_foot_sole" material="left_foot_sole_material"/>
                <!-- replace collision mesh by a box -->
                <geom type="mesh" class="collision" pos="0 0.4 0.1" quat="0.707107 -0.707107 -0 3.77957e-24" mesh="left_foot_sole" material="left_foot_sole_material" name="left_foot_contact"/>
                <!-- <geom type="box" class="collision" pos="0.02 -0.065 -0.02" quat="1.0 0.0 0 0" size="0.1 0.01 0.01" material="left_foot_sole_material" name="left_foot_contact"/> -->



                <!-- Part left_foot_2 -->
                <geom type="mesh" class="visual" pos="-1.38778e-17 0.4 0.1" quat="0.707107 -0.707107 -0 -5.6708e-26" mesh="left_foot" material="left_foot_material"/>
                <!-- Frame left_foot -->
                <site group="3" name="left_foot" pos="0.03 -0.075 -0.02" quat="0.707107 -0.707107 -0 3.77957e-24"/>
              </body>
            </body>
          </body>
        </body>
      </body>
      <!-- Link right_hip_pitch_to_roll -->
      <body name="right_hip_pitch_to_roll" pos="0.120022 -0.00889443 -0.0540277" quat="0.707107 -0.707107 -3.23536e-09 3.23536e-09">
        <!-- Joint from trunk_2 to right_hip_pitch_to_roll -->
        <joint axis="0 0 1" name="right_hip_pitch" type="hinge" range="-1.5707963267948966 1.5707963267948966" class="steadywin_GIM6010_8"/>
        <inertial pos="-0.00539992 2.00931e-10 -0.046622" mass="0.517883" fullinertia="0.000465444 0.000403205 0.000324921 3.16452e-12 -1.58161e-06 1.79213e-12"/>
        <!-- Part gim6010_8_7 -->
        <geom type="mesh" class="visual" pos="-0.02 0 -0.05" quat="0.707107 -0 0.707107 -3.33067e-16" mesh="gim6010_8" material="gim6010_8_material"/>
        <!-- Part right_hip_pitch_to_roll -->
        <geom type="mesh" class="visual" pos="-2.77556e-17 0 0.07" quat="0.707107 0.707107 -0 -2.88869e-25" mesh="right_hip_pitch_to_roll" material="right_hip_pitch_to_roll_material"/>
        <!-- Link right_hip_roll_to_yaw -->
        <body name="right_hip_roll_to_yaw" pos="0.02 -6.93889e-18 -0.05" quat="0.707107 5.26575e-09 -0.707107 -5.26575e-09">
          <!-- Joint from right_hip_pitch_to_roll to right_hip_roll_to_yaw -->
          <joint axis="0 0 1" name="right_hip_roll" type="hinge" range="-0.3490658355050899 1.5707963416886725" class="steadywin_GIM6010_8"/>
          <inertial pos="2.00931e-10 0.0558222 0.0146001" mass="0.517883" fullinertia="0.000696527 0.000428388 0.0006553 7.24941e-12 3.16452e-12 -0.000148243"/>
          <!-- Part right_hip_roll_to_yaw -->
          <geom type="mesh" class="visual" pos="0.12 0 0.02" quat="0.5 0.5 0.5 -0.5" mesh="right_hip_roll_to_yaw" material="right_hip_roll_to_yaw_material"/>
          <!-- Part gim6010_8_8 -->
          <geom type="mesh" class="visual" pos="-2.08167e-17 0.05 0.02" quat="0.5 -0.5 0.5 0.5" mesh="gim6010_8" material="gim6010_8_material"/>
          <!-- Link right_hip_yaw_to_knee -->
          <body name="right_hip_yaw_to_knee" pos="-2.08167e-17 0.09 0.02" quat="0.5 0.5 0.5 -0.5">
            <!-- Joint from right_hip_roll_to_yaw to right_hip_yaw_to_knee -->
            <joint axis="0 0 1" name="right_hip_yaw" type="hinge" range="-1.5707963222194081 1.570796331370385" class="steadywin_GIM6010_8"/>
            <inertial pos="-6.01852e-10 -0.00240575 -0.0825501" mass="0.688" fullinertia="0.00139735 0.00147146 0.000460223 -1.06662e-11 -1.67017e-11 -4.0779e-05"/>
            <!-- Part right_hip_yaw_to_knee -->
            <geom type="mesh" class="visual" pos="0 0.12 0.09" quat="1 -0 -8.67362e-19 1.91719e-16" mesh="right_hip_yaw_to_knee" material="right_hip_yaw_to_knee_material"/>
            <!-- Part gim6010_8_9 -->
            <geom type="mesh" class="visual" pos="1.38778e-17 -0.02 -0.11" quat="0.707107 -0.707107 -0 -9.59898e-25" mesh="gim6010_8" material="gim6010_8_material"/>
            <!-- Link right_knee_to_ankle_pitch -->
            <body name="right_knee_to_ankle_pitch" pos="2.77556e-17 0.02 -0.11" quat="0.707107 0.707107 0 4.31673e-17">
              <!-- Joint from right_hip_yaw_to_knee to right_knee_to_ankle_pitch -->
              <joint axis="0 0 1" name="right_knee" type="hinge" range="-2.2689280275926285 0.0" class="steadywin_GIM6010_8"/>
              <inertial pos="4.82013e-08 -0.149239 0.0200003" mass="0.788" fullinertia="0.00357604 0.000553221 0.00362879 -1.87021e-09 2.32028e-09 0.000244816"/>
              <!-- Part right_knee_to_ankle_pitch -->
              <geom type="mesh" class="visual" pos="-1.38778e-17 0.2 -0.1" quat="0.707107 -0.707107 -0 4.48325e-26" mesh="right_knee_to_ankle_pitch" material="right_knee_to_ankle_pitch_material"/>
              <!-- Part gim6010_8_10 -->
              <geom type="mesh" class="visual" pos="0 -0.2 0.04" quat="0 1 0 0" mesh="gim6010_8" material="gim6010_8_material"/>
              <!-- Link right_foot_2 -->
              <body name="right_foot_2" pos="0 -0.2 4.85723e-17" quat="1 1.55583e-17 1.15648e-18 -2.69444e-25">
                <!-- Joint from right_knee_to_ankle_pitch to right_foot_2 -->
                <joint axis="0 0 1" name="right_ankle_pitch" type="hinge" range="-1.5707963267948966 1.5707963267948966" class="steadywin_GIM6010_8"/>
                <inertial pos="0.0202559 -0.0527376 0.0136201" mass="0.4" fullinertia="0.000426448 0.00107974 0.00139386 0.000143357 -5.16919e-05 0.000119141"/>
                <!-- Part right_foot_2 -->
                <geom type="mesh" class="visual" pos="-1.38778e-17 0.4 -0.1" quat="0.707107 -0.707107 0 -6.3182e-26" mesh="right_foot" material="right_foot_material"/>
                <!-- Part right_foot_sole -->
                <geom type="mesh" class="visual" pos="4.16334e-17 0.4 -0.1" quat="0.707107 -0.707107 -0 -6.31821e-26" mesh="right_foot_sole" material="right_foot_sole_material"/>
                <!-- replace collision mesh by a box -->
                <!-- <geom type="box" class="collision" pos="0.02 -0.065 0.02" quat="1.0 0.0 0 0" size="0.1 0.01 0.01" material="right_foot_sole_material" name="right_foot_contact"/> -->
                <geom type="mesh" class="collision" pos="4.16334e-17 0.4 -0.1" quat="0.707107 -0.707107 -0 -6.31821e-26" mesh="right_foot_sole" material="right_foot_sole_material" name="right_foot_contact"/>
                <!-- Frame right_foot -->
                <site group="3" name="right_foot" pos="0.03 -0.075 0.02" quat="0.707107 -0.707107 -0 -6.31821e-26"/>
              </body>
            </body>
          </body>
        </body>
      </body>
    </body>
  </worldbody>
  <asset>
    <mesh file="trunk.stl"/>
    <mesh file="left_foot_sole.stl"/>
    <mesh file="right_hip_pitch_to_roll.stl"/>
    <mesh file="left_hip_yaw_to_knee.stl"/>
    <mesh file="left_knee_to_ankle_pitch.stl"/>
    <mesh file="right_foot.stl"/>
    <mesh file="right_hip_roll_to_yaw.stl"/>
    <mesh file="right_hip_yaw_to_knee.stl"/>
    <mesh file="right_foot_sole.stl"/>
    <mesh file="left_hip_roll_to_yaw.stl"/>
    <mesh file="left_hip_pitch_to_roll.stl"/>
    <mesh file="gim6010_8.stl"/>
    <mesh file="right_knee_to_ankle_pitch.stl"/>
    <mesh file="left_foot.stl"/>
    <material name="gim6010_8_material" rgba="0.301961 0.301961 0.301961 1"/>
    <material name="trunk_material" rgba="0.615686 0.811765 0.929412 1"/>
    <material name="left_hip_pitch_to_roll_material" rgba="0.647059 0.647059 0.647059 1"/>
    <material name="left_hip_roll_to_yaw_material" rgba="0.231373 0.380392 0.705882 1"/>
    <material name="left_hip_yaw_to_knee_material" rgba="0.917647 0.917647 0.917647 1"/>
    <material name="left_knee_to_ankle_pitch_material" rgba="0.768627 0.886275 0.952941 1"/>
    <material name="left_foot_sole_material" rgba="0.301961 0.301961 0.301961 1"/>
    <material name="left_foot_material" rgba="0.972549 0.529412 0.00392157 1"/>
    <material name="right_hip_pitch_to_roll_material" rgba="0.647059 0.647059 0.647059 1"/>
    <material name="right_hip_roll_to_yaw_material" rgba="0.231373 0.380392 0.705882 1"/>
    <material name="right_hip_yaw_to_knee_material" rgba="0.917647 0.917647 0.917647 1"/>
    <material name="right_knee_to_ankle_pitch_material" rgba="0.768627 0.886275 0.952941 1"/>
    <material name="right_foot_material" rgba="0.972549 0.529412 0.00392157 1"/>
    <material name="right_foot_sole_material" rgba="0.301961 0.301961 0.301961 1"/>
  </asset>
  <actuator>
    <position class="steadywin_GIM6010_8" name="left_hip_pitch" joint="left_hip_pitch" inheritrange="1"/>
    <position class="steadywin_GIM6010_8" name="left_hip_roll" joint="left_hip_roll" inheritrange="1"/>
    <position class="steadywin_GIM6010_8" name="left_hip_yaw" joint="left_hip_yaw" inheritrange="1"/>
    <position class="steadywin_GIM6010_8" name="left_knee" joint="left_knee" inheritrange="1"/>
    <position class="steadywin_GIM6010_8" name="left_ankle_pitch" joint="left_ankle_pitch" inheritrange="1"/>
    <position class="steadywin_GIM6010_8" name="right_hip_pitch" joint="right_hip_pitch" inheritrange="1"/>
    <position class="steadywin_GIM6010_8" name="right_hip_roll" joint="right_hip_roll" inheritrange="1"/>
    <position class="steadywin_GIM6010_8" name="right_hip_yaw" joint="right_hip_yaw" inheritrange="1"/>
    <position class="steadywin_GIM6010_8" name="right_knee" joint="right_knee" inheritrange="1"/>
    <position class="steadywin_GIM6010_8" name="right_ankle_pitch" joint="right_ankle_pitch" inheritrange="1"/>
  </actuator>
  <equality/>
</mujoco>
